<sdf version='1.4'>
  <world name='cart_demo'>
    <physics type='ode'>
      <gravity>0 0 -9.8</gravity>
      <max_step_size>0.001</max_step_size>
      <real_time_factor>10</real_time_factor>
      <real_time_update_rate>1000</real_time_update_rate>
      <ode>
        <solver>
          <type>quick</type>
          <iters>50</iters>
          <sor>1.3</sor>
        </solver>
        <constraints>
          <cfm>0</cfm>
          <erp>0.2</erp>
          <contact_max_correcting_vel>100</contact_max_correcting_vel>
          <contact_surface_layer>0.001</contact_surface_layer>
        </constraints>
      </ode>
      <max_step_size>0.001</max_step_size>
    </physics>
    <light name='sun' type='directional'>
      <pose>0 0 20 0 -0 0</pose>
      <diffuse>0.8 0.8 0.8 1</diffuse>
      <specular>0.1 0.1 0.1 1</specular>
      <attenuation>
        <range>10</range>
        <linear>0.01</linear>
        <constant>0.8</constant>
        <quadratic>0</quadratic>
      </attenuation>
      <direction>0 0.5 -0.5</direction>
      <cast_shadows>1</cast_shadows>
    </light>
    <model name='heightmap'>
      <static>1</static>
      <link name='link'>
        <collision name='collision'>
          <geometry>
            <heightmap>
              <uri>/usr/local/share/gazebo-1.9/media/materials/textures/road2.png</uri>
              <size>256 256 10</size>
              <pos>0 0 0</pos>
              <texture>
                <size>257</size>
                <diffuse>__default__</diffuse>
                <normal>__default__</normal>
              </texture>
              <blend>
                <min_height>0</min_height>
                <fade_dist>0</fade_dist>
              </blend>
            </heightmap>
          </geometry>
          <surface>
            <friction>
              <ode>
                <mu>100</mu>
                <mu2>50</mu2>
              </ode>
            </friction>
            <contact>
              <ode>
                <max_vel>100</max_vel>
              </ode>
            </contact>
            <bounce/>
          </surface>
          <max_contacts>100</max_contacts>
        </collision>
        <visual name='visual'>
          <geometry>
            <heightmap>
              <texture>
                <diffuse>file://media/materials/textures/road1.jpg</diffuse>
                <normal>file://media/materials/textures/flat_normal.png</normal>
                <size>60</size>
              </texture>
              <texture>
                <diffuse>file://media/materials/textures/road1.jpg</diffuse>
                <normal>file://media/materials/textures/flat_normal.png</normal>
                <size>256</size>
              </texture>
              <blend>
                <min_height>0</min_height>
                <fade_dist>60</fade_dist>
              </blend>
              <uri>/usr/local/share/gazebo-1.9/media/materials/textures/road2.png</uri>
              <size>256 256 10</size>
              <pos>0 0 0</pos>
            </heightmap>
          </geometry>
        </visual>
        <velocity_decay>
          <linear>0</linear>
          <angular>0</angular>
        </velocity_decay>
        <self_collide>1</self_collide>
        <kinematic>0</kinematic>
        <gravity>1</gravity>
      </link>
    </model>
    <scene>
      <ambient>0.4 0.4 0.4 1</ambient>
      <background>0.7 0.7 0.7 1</background>
      <shadows>1</shadows>
    </scene>
    <spherical_coordinates>
      <surface_model>EARTH_WGS84</surface_model>
      <latitude_deg>0</latitude_deg>
      <longitude_deg>0</longitude_deg>
      <elevation>0</elevation>
      <heading_deg>0</heading_deg>
    </spherical_coordinates>
    <model name='test_model'>
      <pose>20 21 4.2 0 -0 0</pose>
      <link name='link'>
        <inertial>
          <inertia>
            <ixx>1</ixx>
            <ixy>0</ixy>
            <ixz>0</ixz>
            <iyy>1</iyy>
            <iyz>0</iyz>
            <izz>1</izz>
          </inertia>
          <mass>21</mass>
        </inertial>
        <collision name='collision'>
          <pose>0 0 0 0 -0 0</pose>
          <geometry>
            <box>
              <size>1 1 0.1</size>
            </box>
          </geometry>
          <surface>
            <friction>
              <ode>
                <mu>1</mu>
                <mu2>1</mu2>
              </ode>
            </friction>
            <contact>
              <ode>
                <max_vel>100</max_vel>
              </ode>
            </contact>
            <bounce/>
          </surface>
          <max_contacts>10</max_contacts>
        </collision>
        <visual name='visual'>
          <pose>0 0 -0.55 0 -0 0</pose>
          <geometry>
            <box>
              <size>1 1 0.1</size>
            </box>
          </geometry>
          <material>
            <script>
              <uri>file://media/materials/scripts/gazebo.material</uri>
              <name>Gazebo/Green</name>
            </script>
          </material>
        </visual>
        <velocity_decay>
          <linear>0</linear>
          <angular>0</angular>
        </velocity_decay>
        <self_collide>0</self_collide>
        <kinematic>0</kinematic>
        <gravity>1</gravity>
      </link>
      <link name='bar_1'>
        <pose>0.45 0 -0.5 0 -0 0</pose>
        <inertial>
          <inertia>
            <ixx>0.001</ixx>
            <ixy>0</ixy>
            <ixz>0</ixz>
            <iyy>0.001</iyy>
            <iyz>0</iyz>
            <izz>0.001</izz>
          </inertia>
          <mass>0.1</mass>
        </inertial>
        <collision name='collision'>
          <geometry>
            <box>
              <size>0.06 1 0.02</size>
            </box>
          </geometry>
          <surface>
            <friction>
              <ode>
                <mu>1</mu>
                <mu2>1</mu2>
              </ode>
            </friction>
            <contact>
              <ode>
                <max_vel>100</max_vel>
              </ode>
            </contact>
            <bounce/>
          </surface>
          <max_contacts>10</max_contacts>
        </collision>
        <visual name='visual'>
          <geometry>
            <box>
              <size>0.02 1 0.02</size>
            </box>
          </geometry>
          <material>
            <script>
              <uri>file://media/materials/scripts/gazebo.material</uri>
              <name>Gazebo/Yellow</name>
            </script>
          </material>
        </visual>
        <velocity_decay>
          <linear>0</linear>
          <angular>0</angular>
        </velocity_decay>
        <self_collide>0</self_collide>
        <kinematic>0</kinematic>
        <gravity>1</gravity>
      </link>
      <joint name='bar_12_joint' type='revolute'>
        <parent>bar_2</parent>
        <child>bar_1</child>
        <pose>0 0.5 0 0 -0 0</pose>
        <axis>
          <xyz>0 0 1</xyz>
          <limit>
            <lower>-1e+16</lower>
            <upper>1e+16</upper>
          </limit>
        </axis>
      </joint>
      <joint name='bar_13_joint' type='revolute'>
        <parent>bar_3</parent>
        <child>bar_1</child>
        <pose>0 -0.5 0 0 -0 0</pose>
        <axis>
          <xyz>0 0 1</xyz>
          <limit>
            <lower>-1e+16</lower>
            <upper>1e+16</upper>
          </limit>
        </axis>
      </joint>
      <link name='bar_2'>
        <pose>0.5 0.5 -0.5 0 -0 0</pose>
        <inertial>
          <inertia>
            <ixx>0.001</ixx>
            <ixy>0</ixy>
            <ixz>0</ixz>
            <iyy>0.001</iyy>
            <iyz>0</iyz>
            <izz>0.001</izz>
          </inertia>
          <mass>0.1</mass>
        </inertial>
        <collision name='collision'>
          <pose>-0.025 0 0 0 -0 0</pose>
          <geometry>
            <box>
              <size>0.08 0.05 0.05</size>
            </box>
          </geometry>
          <surface>
            <friction>
              <ode>
                <mu>1</mu>
                <mu2>1</mu2>
              </ode>
            </friction>
            <contact>
              <ode>
                <max_vel>100</max_vel>
              </ode>
            </contact>
            <bounce/>
          </surface>
          <max_contacts>10</max_contacts>
        </collision>
        <visual name='visual'>
          <pose>-0.025 0 0 0 -0 0</pose>
          <geometry>
            <box>
              <size>0.05 0.02 0.02</size>
            </box>
          </geometry>
          <material>
            <script>
              <uri>file://media/materials/scripts/gazebo.material</uri>
              <name>Gazebo/Black</name>
            </script>
          </material>
        </visual>
        <velocity_decay>
          <linear>0</linear>
          <angular>0</angular>
        </velocity_decay>
        <self_collide>0</self_collide>
        <kinematic>0</kinematic>
        <gravity>1</gravity>
      </link>
      <joint name='bar_2_joint' type='revolute'>
        <parent>link</parent>
        <child>bar_2</child>
        <pose>0 0 0 0 -0 0</pose>
        <axis>
          <xyz>0 0 1</xyz>
          <limit>
            <lower>-7.853</lower>
            <upper>7.853</upper>
          </limit>
        </axis>
      </joint>
      <link name='bar_3'>
        <pose>0.5 -0.5 -0.5 0 -0 0</pose>
        <inertial>
          <inertia>
            <ixx>0.001</ixx>
            <ixy>0</ixy>
            <ixz>0</ixz>
            <iyy>0.001</iyy>
            <iyz>0</iyz>
            <izz>0.001</izz>
          </inertia>
          <mass>0.1</mass>
        </inertial>
        <collision name='collision'>
          <pose>-0.025 0 0 0 -0 0</pose>
          <geometry>
            <box>
              <size>0.05 0.02 0.02</size>
            </box>
          </geometry>
          <surface>
            <friction>
              <ode>
                <mu>1</mu>
                <mu2>1</mu2>
              </ode>
            </friction>
            <contact>
              <ode>
                <max_vel>100</max_vel>
              </ode>
            </contact>
            <bounce/>
          </surface>
          <max_contacts>10</max_contacts>
        </collision>
        <visual name='visual'>
          <pose>-0.025 0 0 0 -0 0</pose>
          <geometry>
            <box>
              <size>0.05 0.02 0.02</size>
            </box>
          </geometry>
          <material>
            <script>
              <uri>file://media/materials/scripts/gazebo.material</uri>
              <name>Gazebo/Black</name>
            </script>
          </material>
        </visual>
        <velocity_decay>
          <linear>0</linear>
          <angular>0</angular>
        </velocity_decay>
        <self_collide>0</self_collide>
        <kinematic>0</kinematic>
        <gravity>1</gravity>
      </link>
      <joint name='bar_3_joint' type='revolute'>
        <parent>link</parent>
        <child>bar_3</child>
        <pose>0 0 0 0 -0 0</pose>
        <axis>
          <xyz>0 0 1</xyz>
          <limit>
            <lower>-1e+16</lower>
            <upper>1e+16</upper>
          </limit>
        </axis>
      </joint>
      <link name='wheel_1'>
        <pose>0.5 0.55 -0.5 1.5708 -0 0</pose>
        <inertial>
          <inertia>
            <ixx>0.01</ixx>
            <ixy>0</ixy>
            <ixz>0</ixz>
            <iyy>0.01</iyy>
            <iyz>0</iyz>
            <izz>0.01</izz>
          </inertia>
          <mass>1</mass>
        </inertial>
        <collision name='collision'>
          <geometry>
            <cylinder>
              <radius>0.2</radius>
              <length>0.1</length>
            </cylinder>
          </geometry>
          <surface>
            <friction>
              <ode>
                <fdir1>1 0 0</fdir1>
                <mu>1</mu>
                <mu2>1</mu2>
              </ode>
            </friction>
            <contact>
              <ode>
                <max_vel>100</max_vel>
              </ode>
            </contact>
            <bounce/>
          </surface>
          <max_contacts>10</max_contacts>
        </collision>
        <visual name='visual'>
          <geometry>
            <cylinder>
              <radius>0.2</radius>
              <length>0.1</length>
            </cylinder>
          </geometry>
          <material>
            <script>
              <uri>file://media/materials/scripts/gazebo.material</uri>
              <name>Gazebo/White</name>
            </script>
          </material>
        </visual>
        <velocity_decay>
          <linear>0</linear>
          <angular>0</angular>
        </velocity_decay>
        <self_collide>0</self_collide>
        <kinematic>0</kinematic>
        <gravity>1</gravity>
      </link>
      <joint name='wheel_1_joint' type='revolute'>
        <parent>bar_2</parent>
        <child>wheel_1</child>
        <pose>0 0 0 0 -0 0</pose>
        <axis>
          <xyz>0 1 0</xyz>
          <limit>
            <lower>-1e+16</lower>
            <upper>1e+16</upper>
          </limit>
        </axis>
      </joint>
      <link name='wheel_2'>
        <pose>0.5 -0.55 -0.5 1.5708 -0 0</pose>
        <inertial>
          <inertia>
            <ixx>0.01</ixx>
            <ixy>0</ixy>
            <ixz>0</ixz>
            <iyy>0.01</iyy>
            <iyz>0</iyz>
            <izz>0.01</izz>
          </inertia>
          <mass>1</mass>
        </inertial>
        <collision name='collision'>
          <geometry>
            <cylinder>
              <radius>0.2</radius>
              <length>0.1</length>
            </cylinder>
          </geometry>
          <surface>
            <friction>
              <ode>
                <fdir1>1 0 0</fdir1>
                <mu>1</mu>
                <mu2>1</mu2>
              </ode>
            </friction>
            <contact>
              <ode>
                <max_vel>100</max_vel>
              </ode>
            </contact>
            <bounce/>
          </surface>
          <max_contacts>10</max_contacts>
        </collision>
        <visual name='visual'>
          <geometry>
            <cylinder>
              <radius>0.2</radius>
              <length>0.1</length>
            </cylinder>
          </geometry>
          <material>
            <script>
              <uri>file://media/materials/scripts/gazebo.material</uri>
              <name>Gazebo/White</name>
            </script>
          </material>
        </visual>
        <velocity_decay>
          <linear>0</linear>
          <angular>0</angular>
        </velocity_decay>
        <self_collide>0</self_collide>
        <kinematic>0</kinematic>
        <gravity>1</gravity>
      </link>
      <joint name='wheel_2_joint' type='revolute'>
        <parent>bar_3</parent>
        <child>wheel_2</child>
        <pose>0 0 0 0 -0 0</pose>
        <axis>
          <xyz>0 1 0</xyz>
          <limit>
            <lower>-1e+16</lower>
            <upper>1e+16</upper>
          </limit>
        </axis>
      </joint>
      <link name='wheel_3'>
        <pose>-0.5 0.55 -0.5 1.5708 -0 0</pose>
        <inertial>
          <inertia>
            <ixx>0.01</ixx>
            <ixy>0</ixy>
            <ixz>0</ixz>
            <iyy>0.01</iyy>
            <iyz>0</iyz>
            <izz>0.01</izz>
          </inertia>
          <mass>1</mass>
        </inertial>
        <collision name='collision'>
          <geometry>
            <cylinder>
              <radius>0.2</radius>
              <length>0.1</length>
            </cylinder>
          </geometry>
          <surface>
            <friction>
              <ode>
                <fdir1>1 0 0</fdir1>
                <mu>1</mu>
                <mu2>1</mu2>
              </ode>
            </friction>
            <contact>
              <ode>
                <max_vel>100</max_vel>
              </ode>
            </contact>
            <bounce/>
          </surface>
          <max_contacts>10</max_contacts>
        </collision>
        <visual name='visual'>
          <geometry>
            <cylinder>
              <radius>0.2</radius>
              <length>0.1</length>
            </cylinder>
          </geometry>
          <material>
            <script>
              <uri>file://media/materials/scripts/gazebo.material</uri>
              <name>Gazebo/Black</name>
            </script>
          </material>
        </visual>
        <velocity_decay>
          <linear>0</linear>
          <angular>0</angular>
        </velocity_decay>
        <self_collide>0</self_collide>
        <kinematic>0</kinematic>
        <gravity>1</gravity>
      </link>
      <joint name='wheel_3_joint' type='revolute'>
        <parent>link</parent>
        <child>wheel_3</child>
        <pose>0 0 0 0 -0 0</pose>
        <axis>
          <dynamics>
            <damping>0</damping>
            <friction>0</friction>
          </dynamics>
          <xyz>0 1 0</xyz>
          <limit>
            <lower>-1e+16</lower>
            <upper>1e+16</upper>
          </limit>
        </axis>
      </joint>
      <link name='wheel_4'>
        <pose>-0.5 -0.55 -0.5 1.5708 -0 0</pose>
        <inertial>
          <inertia>
            <ixx>0.01</ixx>
            <ixy>0</ixy>
            <ixz>0</ixz>
            <iyy>0.01</iyy>
            <iyz>0</iyz>
            <izz>0.01</izz>
          </inertia>
          <mass>1</mass>
        </inertial>
        <collision name='collision'>
          <geometry>
            <cylinder>
              <radius>0.2</radius>
              <length>0.1</length>
            </cylinder>
          </geometry>
          <surface>
            <friction>
              <ode>
                <fdir1>1 0 0</fdir1>
                <mu>1</mu>
                <mu2>1</mu2>
              </ode>
            </friction>
            <contact>
              <ode>
                <max_vel>100</max_vel>
              </ode>
            </contact>
            <bounce/>
          </surface>
          <max_contacts>10</max_contacts>
        </collision>
        <visual name='visual'>
          <geometry>
            <cylinder>
              <radius>0.2</radius>
              <length>0.1</length>
            </cylinder>
          </geometry>
          <material>
            <script>
              <uri>file://media/materials/scripts/gazebo.material</uri>
              <name>Gazebo/Black</name>
            </script>
          </material>
        </visual>
        <velocity_decay>
          <linear>0</linear>
          <angular>0</angular>
        </velocity_decay>
        <self_collide>0</self_collide>
        <kinematic>0</kinematic>
        <gravity>1</gravity>
      </link>
      <joint name='wheel_4_joint' type='revolute'>
        <parent>link</parent>
        <child>wheel_4</child>
        <pose>0 0 0 0 -0 0</pose>
        <axis>
          <dynamics>
            <damping>0</damping>
            <friction>0</friction>
          </dynamics>
          <xyz>0 1 0</xyz>
          <limit>
            <lower>-1e+16</lower>
            <upper>1e+16</upper>
          </limit>
        </axis>
      </joint>
      <link name='gas_pedal'>
        <pose>0.1 -0.1 -0.1 0 -0 0</pose>
        <inertial>
          <inertia>
            <ixx>0.001</ixx>
            <ixy>0</ixy>
            <ixz>0</ixz>
            <iyy>0.001</iyy>
            <iyz>0</iyz>
            <izz>0.001</izz>
          </inertia>
          <mass>0.1</mass>
        </inertial>
        <collision name='collision'>
          <pose>0.04 0 0 0 -0 0</pose>
          <geometry>
            <box>
              <size>0.05 0.02 0.02</size>
            </box>
          </geometry>
          <surface>
            <friction>
              <ode>
                <mu>1</mu>
                <mu2>1</mu2>
              </ode>
            </friction>
            <contact>
              <ode>
                <max_vel>100</max_vel>
              </ode>
            </contact>
            <bounce/>
          </surface>
          <max_contacts>10</max_contacts>
        </collision>
        <visual name='visual'>
          <pose>-0.025 0 0 0 -0 0</pose>
          <geometry>
            <box>
              <size>0.05 0.02 0.02</size>
            </box>
          </geometry>
          <material>
            <script>
              <uri>file://media/materials/scripts/gazebo.material</uri>
              <name>Gazebo/Blue</name>
            </script>
          </material>
        </visual>
        <velocity_decay>
          <linear>0</linear>
          <angular>0</angular>
        </velocity_decay>
        <self_collide>0</self_collide>
        <kinematic>0</kinematic>
        <gravity>1</gravity>
      </link>
      <joint name='gas_joint' type='prismatic'>
        <parent>link</parent>
        <child>gas_pedal</child>
        <axis>
          <xyz>1 0 0</xyz>
          <limit>
            <lower>0</lower>
            <upper>0.2</upper>
          </limit>
        </axis>
      </joint>
      <link name='brake_pedal'>
        <pose>0.1 0.1 -0.1 0 -0 0</pose>
        <inertial>
          <inertia>
            <ixx>0.001</ixx>
            <ixy>0</ixy>
            <ixz>0</ixz>
            <iyy>0.001</iyy>
            <iyz>0</iyz>
            <izz>0.001</izz>
          </inertia>
          <mass>0.1</mass>
        </inertial>
        <collision name='collision'>
          <pose>0.04 0 0 0 -0 0</pose>
          <geometry>
            <box>
              <size>0.05 0.02 0.02</size>
            </box>
          </geometry>
          <surface>
            <friction>
              <ode>
                <mu>1</mu>
                <mu2>1</mu2>
              </ode>
            </friction>
            <contact>
              <ode>
                <max_vel>100</max_vel>
              </ode>
            </contact>
            <bounce/>
          </surface>
          <max_contacts>10</max_contacts>
        </collision>
        <visual name='visual'>
          <pose>0.04 0 0 0 -0 0</pose>
          <geometry>
            <box>
              <size>0.05 0.02 0.02</size>
            </box>
          </geometry>
          <material>
            <script>
              <uri>file://media/materials/scripts/gazebo.material</uri>
              <name>Gazebo/Red</name>
            </script>
          </material>
        </visual>
        <velocity_decay>
          <linear>0</linear>
          <angular>0</angular>
        </velocity_decay>
        <self_collide>0</self_collide>
        <kinematic>0</kinematic>
        <gravity>1</gravity>
      </link>
      <joint name='brake_joint' type='prismatic'>
        <parent>link</parent>
        <child>brake_pedal</child>
        <axis>
          <xyz>1 0 0</xyz>
          <limit>
            <lower>0</lower>
            <upper>0.2</upper>
          </limit>
        </axis>
      </joint>
      <plugin name='cart_test_plugin' filename='libCartDemoPlugin.so'>
        <steer>bar_2_joint</steer>
        <steer_pid>10 0.1 0.5</steer_pid>
        <steer_ilim>-10 10</steer_ilim>
        <steer_pos>0.0</steer_pos>
        <steer_vel>0</steer_vel>
        <steer_eff>100.0</steer_eff>
        <right>wheel_3_joint</right>
        <right_pid>0.1 0.0 0.001</right_pid>
        <right_ilim>-.1 .1</right_ilim>
        <right_pos>0</right_pos>
        <right_vel>0</right_vel>
        <right_eff>0.1</right_eff>
        <left>wheel_4_joint</left>
        <left_pid>0.1 0.0 0.001</left_pid>
        <left_ilim>-.1 .1</left_ilim>
        <left_pos>0</left_pos>
        <left_vel>0</left_vel>
        <left_eff>0.1</left_eff>
        <gas>gas_joint</gas>
        <gas_pid>12 2 0</gas_pid>
        <gas_ilim>-3 3</gas_ilim>
        <brake>brake_joint</brake>
        <brake_pid>-10.129 -1.02 0</brake_pid>
        <brake_ilim>-3 .3</brake_ilim>
        <front_power>10</front_power>
        <rear_power>10</rear_power>
        <tire_angle_range>0.5</tire_angle_range>
        <max_speed>10</max_speed>
        <aero_load>0.1</aero_load>
      </plugin>
      <static>0</static>
    </model>
    <state world_name='cart_demo'>
      <sim_time>0 0</sim_time>
      <real_time>0 0</real_time>
      <wall_time></wall_time>
      <model name='heightmap'>
        <pose>0 0 0 0 -0 0</pose>
        <link name='link'>
          <pose>0 0 0 0 -0 0</pose>
          <velocity>0 0 0 0 -0 0</velocity>
          <acceleration>0 0 0 0 -0 0</acceleration>
          <wrench>0 0 0 0 -0 0</wrench>
        </link>
      </model>
      <model name='test_model'>
        <pose>20.05 20.917 0.699993 1.65436e-24 -1e-06 3.13412</pose>
        <link name='bar_1'>
          <pose>19.6 20.9204 0.199995 -3e-06 -0 3.13412</pose>
          <velocity>-0.002267 -0.000602 0.000219 -0.000662 0.008406 -0.00042</velocity>
          <acceleration>0 0 0 0 -0 0</acceleration>
          <wrench>0 0 0 0 -0 0</wrench>
        </link>
        <link name='bar_2'>
          <pose>19.5463 20.4208 0.2 2e-06 -1e-06 3.13423</pose>
          <velocity>-0.002193 -0.000856 -5.4e-05 0.000264 0.008256 0.012036</velocity>
          <acceleration>0 0 0 0 -0 0</acceleration>
          <wrench>0 0 0 0 -0 0</wrench>
        </link>
        <link name='bar_3'>
          <pose>19.5537 21.4207 0.200003 8.27181e-25 -1e-06 3.13425</pose>
          <velocity>-0.002232 0.000383 -0.000293 -0.000237 0.008351 -0.015783</velocity>
          <acceleration>0 0 0 0 -0 0</acceleration>
          <wrench>0 0 0 0 -0 0</wrench>
        </link>
        <link name='brake_pedal'>
          <pose>19.7494 20.8193 0.599992 -1e-06 2e-06 3.13412</pose>
          <velocity>0.001279 -0.000118 -0.000394 -0.000287 0.008761 1.9e-05</velocity>
          <acceleration>0 0 0 0 -0 0</acceleration>
          <wrench>0 0 0 0 -0 0</wrench>
        </link>
        <link name='gas_pedal'>
          <pose>19.7511 21.0193 0.599992 1e-06 2e-06 3.13412</pose>
          <velocity>0.001312 -0.000122 -0.000435 2.5e-05 0.00876 2.1e-05</velocity>
          <acceleration>0 0 0 0 -0 0</acceleration>
          <wrench>0 0 0 0 -0 0</wrench>
        </link>
        <link name='link'>
          <pose>20.05 20.917 0.699993 1.65436e-24 -1e-06 3.13412</pose>
          <velocity>0.002027 -9.7e-05 -0.002971 -0.000138 0.008262 3.3e-05</velocity>
          <acceleration>0 0 0 0 -0 0</acceleration>
          <wrench>0 0 0 0 -0 0</wrench>
        </link>
        <link name='wheel_1'>
          <pose>19.5459 20.3708 0.2 1.57078 -0.696879 3.13425</pose>
          <velocity>-0.00155 -0.000118 -6.7e-05 0.000552 -0.004018 0.014885</velocity>
          <acceleration>0 0 0 0 -0 0</acceleration>
          <wrench>0 0 0 0 -0 0</wrench>
        </link>
        <link name='wheel_2'>
          <pose>19.5541 21.4707 0.200001 1.57082 -0.06156 3.13425</pose>
          <velocity>-0.0016 0.000343 -7.4e-05 -0.001594 -0.00425 -0.014967</velocity>
          <acceleration>0 0 0 0 -0 0</acceleration>
          <wrench>0 0 0 0 -0 0</wrench>
        </link>
        <link name='wheel_3'>
          <pose>20.5458 20.3633 0.199993 1.5708 1.22194 3.13412</pose>
          <velocity>-0.002166 -0.000184 -0.007109 -5.6e-05 0.023322 2.5e-05</velocity>
          <acceleration>0 0 0 0 -0 0</acceleration>
          <wrench>0 0 0 0 -0 0</wrench>
        </link>
        <link name='wheel_4'>
          <pose>20.5541 21.4633 0.199993 1.5708 0.676422 3.13412</pose>
          <velocity>-0.002154 -0.000149 -0.007398 -0.000222 0.024627 3.5e-05</velocity>
          <acceleration>0 0 0 0 -0 0</acceleration>
          <wrench>0 0 0 0 -0 0</wrench>
        </link>
      </model>
    </state>
    <gui fullscreen='0'>
      <camera name='user_camera'>
        <pose>19.4297 20.2142 11.9307 0 1.4938 -3.06781</pose>
        <view_controller>orbit</view_controller>
      </camera>
    </gui>
  </world>
</sdf>
